<mujoco model="vention">
  <compiler autolimits="true" angle="radian"/>
  <option impratio="10" integrator="implicitfast" cone="elliptic"/>
  <default>
    <default class="/">
      <default class="vention">
        <default class="visual">
          <geom type="mesh" contype="0" conaffinity="0" group="2"/>
        </default>
        <default class="collision">
          <geom type="mesh" group="3" rgba="0.69999999999999996 0.69999999999999996 0.69999999999999996 0.90000000000000002"/>
        </default>
      </default>
    </default>
    <default class="left_ur5e/">
      <default class="left_ur5e/ur5e">
        <material specular="0.5" shininess="0.25"/>
        <joint axis="0 1 0" range="-3.1415000000000002 3.1415000000000002" armature="0.10000000000000001"/>
        <site group="4" rgba="0.5 0.5 0.5 0.29999999999999999" size="0.01"/>
        <general ctrlrange="-3.1415000000000002 3.1415000000000002" forcerange="-150 150" gaintype="fixed" biastype="affine" gainprm="2000" biasprm="0 -2000 -400"/>
        <default class="left_ur5e/size1">
          <general forcerange="-28 28" gainprm="500" biasprm="0 -500 -100"/>
        </default>
        <default class="left_ur5e/visual">
          <geom type="mesh" contype="0" conaffinity="0" group="2"/>
        </default>
        <default class="left_ur5e/collision">
          <geom type="capsule" group="3"/>
          <default class="left_ur5e/eef_collision">
            <geom type="cylinder"/>
          </default>
        </default>
      </default>
    </default>
    <default class="right_ur5e/">
      <default class="right_ur5e/ur5e">
        <material specular="0.5" shininess="0.25"/>
        <joint axis="0 1 0" range="-3.1415000000000002 3.1415000000000002" armature="0.10000000000000001"/>
        <site group="4" rgba="0.5 0.5 0.5 0.29999999999999999" size="0.01"/>
        <general ctrlrange="-3.1415000000000002 3.1415000000000002" forcerange="-150 150" gaintype="fixed" biastype="affine" gainprm="2000" biasprm="0 -2000 -400"/>
        <default class="right_ur5e/size1">
          <general forcerange="-28 28" gainprm="500" biasprm="0 -500 -100"/>
        </default>
        <default class="right_ur5e/visual">
          <geom type="mesh" contype="0" conaffinity="0" group="2"/>
        </default>
        <default class="right_ur5e/collision">
          <geom type="capsule" group="3"/>
          <default class="right_ur5e/eef_collision">
            <geom type="cylinder"/>
          </default>
        </default>
      </default>
    </default>
    <default class="right_ur5e/gripper/">
      <default class="right_ur5e/gripper/2f140">
        <joint axis="1 0 0"/>
        <general biastype="affine"/>
        <default class="right_ur5e/gripper/driver">
          <joint solreflimit="0.0050000000000000001 1" solimplimit="0.94999999999999996 0.98999999999999999 0.001" range="-0.80000000000000004 0" armature="0.0050000000000000001" damping="0.10000000000000001"/>
        </default>
        <default class="right_ur5e/gripper/follower">
          <joint pos="0 0.0050000000000000001 -0.017500000000000002" solreflimit="0.0050000000000000001 1" solimplimit="0.94999999999999996 0.98999999999999999 0.001" range="-0.87570000000000003 0.87570000000000003" armature="0.001"/>
        </default>
        <default class="right_ur5e/gripper/spring_link">
          <joint stiffness="0.050000000000000003" range="-0.80000000000000004 0.29670597283" springref="-25.620000000000001" armature="0.001" damping="0.00125"/>
        </default>
        <default class="right_ur5e/gripper/coupler">
          <joint solreflimit="0.0050000000000000001 1" solimplimit="0.94999999999999996 0.98999999999999999 0.001" range="0 1.5700000000000001" armature="0.001"/>
        </default>
        <default class="right_ur5e/gripper/visual">
          <geom type="mesh" contype="0" conaffinity="0" group="2"/>
        </default>
        <default class="right_ur5e/gripper/collision">
          <geom type="mesh" group="3"/>
          <default class="right_ur5e/gripper/pad_box1">
            <geom type="box" priority="1" size="0.0135 0.032500000000000001 0.0037499999999999999" rgba="0.55000000000000004 0.55000000000000004 0.55000000000000004 1" friction="0.69999999999999996" mass="0" solref="0.0040000000000000001 1" solimp="0.94999999999999996 0.98999999999999999 0.001" pos="0 0.045755400000000002 -0.027220299999999999"/>
          </default>
        </default>
      </default>
    </default>
    <default class="camera_with_mount/"/>
  </default>
  <asset>
    <material name="blue" class="/" rgba="0.050000000000000003 0.050000000000000003 0.90000000000000002 1"/>
    <material name="red" class="/" rgba="1 0.072272000000000003 0.039545999999999998 1"/>
    <mesh name="vention_frame_visual_model" class="/" file="vention_frame_visual_model-3ad6025d0633a8c49789e10339a2c0fb6855dd81.stl"/>
    <material name="left_ur5e/black" class="left_ur5e/ur5e" rgba="0.033000000000000002 0.033000000000000002 0.033000000000000002 1"/>
    <material name="left_ur5e/jointgray" class="left_ur5e/ur5e" rgba="0.27800000000000002 0.27800000000000002 0.27800000000000002 1"/>
    <material name="left_ur5e/linkgray" class="left_ur5e/ur5e" rgba="0.81999999999999995 0.81999999999999995 0.81999999999999995 1"/>
    <material name="left_ur5e/urblue" class="left_ur5e/ur5e" rgba="0.48999999999999999 0.67800000000000005 0.80000000000000004 1"/>
    <mesh name="left_ur5e/base_0" class="left_ur5e/" file="base_0-d5328a99917358d9aa384f12743fe73698461d1c.obj"/>
    <mesh name="left_ur5e/base_1" class="left_ur5e/" file="base_1-d1c667ae5f87b9c900fdeadad850205153846396.obj"/>
    <mesh name="left_ur5e/shoulder_0" class="left_ur5e/" file="shoulder_0-89051b80580d45ef39cb220bf068742b01770552.obj"/>
    <mesh name="left_ur5e/shoulder_1" class="left_ur5e/" file="shoulder_1-50ba15e82459989cf7f17cba7b1aafbca2781206.obj"/>
    <mesh name="left_ur5e/shoulder_2" class="left_ur5e/" file="shoulder_2-29ad171bec79e2912abb81d250aaf5ff9a67bc60.obj"/>
    <mesh name="left_ur5e/upperarm_0" class="left_ur5e/" file="upperarm_0-16bfdf8d1b19d35ef0adbc4cf29ab0c7edb62dcf.obj"/>
    <mesh name="left_ur5e/upperarm_1" class="left_ur5e/" file="upperarm_1-c53724435bec35e1b608145457af767b038f4fd1.obj"/>
    <mesh name="left_ur5e/upperarm_2" class="left_ur5e/" file="upperarm_2-199e0d0c1baa55a078742ed298800ff26d072c09.obj"/>
    <mesh name="left_ur5e/upperarm_3" class="left_ur5e/" file="upperarm_3-62f2bba935d9ab94800a49bcb6ede7b0fa9dd071.obj"/>
    <mesh name="left_ur5e/forearm_0" class="left_ur5e/" file="forearm_0-7994229075bdd0e4a5c860ca174278ee8eda8229.obj"/>
    <mesh name="left_ur5e/forearm_1" class="left_ur5e/" file="forearm_1-c72848167eef89e0d9801ddd7da516e7e878776e.obj"/>
    <mesh name="left_ur5e/forearm_2" class="left_ur5e/" file="forearm_2-3a33518f421ed893ff9b0d759af07b0e5900e78c.obj"/>
    <mesh name="left_ur5e/forearm_3" class="left_ur5e/" file="forearm_3-54cad2556a94cdda04a7cef5c84554a7d9f3ab03.obj"/>
    <mesh name="left_ur5e/wrist1_0" class="left_ur5e/" file="wrist1_0-6876ccb9d0084054268dd6aec007e5a61aea6c2d.obj"/>
    <mesh name="left_ur5e/wrist1_1" class="left_ur5e/" file="wrist1_1-0f7e6640a9dfb98e58078997f5f82bd433879387.obj"/>
    <mesh name="left_ur5e/wrist1_2" class="left_ur5e/" file="wrist1_2-3f6dcae8c736e2c42db3746db7f24ac4516aaca7.obj"/>
    <mesh name="left_ur5e/wrist2_0" class="left_ur5e/" file="wrist2_0-fdb3f7bc360f8f37f6be6270c8b507291dc9b01c.obj"/>
    <mesh name="left_ur5e/wrist2_1" class="left_ur5e/" file="wrist2_1-258ca475798c530d954723dc29f3d67086ead0d9.obj"/>
    <mesh name="left_ur5e/wrist2_2" class="left_ur5e/" file="wrist2_2-c6734971531db7f2f09e746377aa9faccb69b192.obj"/>
    <mesh name="left_ur5e/wrist3" class="left_ur5e/" file="wrist3-a1fffb4f599e121fb18be40e087b6fd7fb164e59.obj"/>
    <material name="right_ur5e/black" class="right_ur5e/ur5e" rgba="0.033000000000000002 0.033000000000000002 0.033000000000000002 1"/>
    <material name="right_ur5e/jointgray" class="right_ur5e/ur5e" rgba="0.27800000000000002 0.27800000000000002 0.27800000000000002 1"/>
    <material name="right_ur5e/linkgray" class="right_ur5e/ur5e" rgba="0.81999999999999995 0.81999999999999995 0.81999999999999995 1"/>
    <material name="right_ur5e/urblue" class="right_ur5e/ur5e" rgba="0.48999999999999999 0.67800000000000005 0.80000000000000004 1"/>
    <mesh name="right_ur5e/base_0" class="right_ur5e/" file="base_0-d5328a99917358d9aa384f12743fe73698461d1c.obj"/>
    <mesh name="right_ur5e/base_1" class="right_ur5e/" file="base_1-d1c667ae5f87b9c900fdeadad850205153846396.obj"/>
    <mesh name="right_ur5e/shoulder_0" class="right_ur5e/" file="shoulder_0-89051b80580d45ef39cb220bf068742b01770552.obj"/>
    <mesh name="right_ur5e/shoulder_1" class="right_ur5e/" file="shoulder_1-50ba15e82459989cf7f17cba7b1aafbca2781206.obj"/>
    <mesh name="right_ur5e/shoulder_2" class="right_ur5e/" file="shoulder_2-29ad171bec79e2912abb81d250aaf5ff9a67bc60.obj"/>
    <mesh name="right_ur5e/upperarm_0" class="right_ur5e/" file="upperarm_0-16bfdf8d1b19d35ef0adbc4cf29ab0c7edb62dcf.obj"/>
    <mesh name="right_ur5e/upperarm_1" class="right_ur5e/" file="upperarm_1-c53724435bec35e1b608145457af767b038f4fd1.obj"/>
    <mesh name="right_ur5e/upperarm_2" class="right_ur5e/" file="upperarm_2-199e0d0c1baa55a078742ed298800ff26d072c09.obj"/>
    <mesh name="right_ur5e/upperarm_3" class="right_ur5e/" file="upperarm_3-62f2bba935d9ab94800a49bcb6ede7b0fa9dd071.obj"/>
    <mesh name="right_ur5e/forearm_0" class="right_ur5e/" file="forearm_0-7994229075bdd0e4a5c860ca174278ee8eda8229.obj"/>
    <mesh name="right_ur5e/forearm_1" class="right_ur5e/" file="forearm_1-c72848167eef89e0d9801ddd7da516e7e878776e.obj"/>
    <mesh name="right_ur5e/forearm_2" class="right_ur5e/" file="forearm_2-3a33518f421ed893ff9b0d759af07b0e5900e78c.obj"/>
    <mesh name="right_ur5e/forearm_3" class="right_ur5e/" file="forearm_3-54cad2556a94cdda04a7cef5c84554a7d9f3ab03.obj"/>
    <mesh name="right_ur5e/wrist1_0" class="right_ur5e/" file="wrist1_0-6876ccb9d0084054268dd6aec007e5a61aea6c2d.obj"/>
    <mesh name="right_ur5e/wrist1_1" class="right_ur5e/" file="wrist1_1-0f7e6640a9dfb98e58078997f5f82bd433879387.obj"/>
    <mesh name="right_ur5e/wrist1_2" class="right_ur5e/" file="wrist1_2-3f6dcae8c736e2c42db3746db7f24ac4516aaca7.obj"/>
    <mesh name="right_ur5e/wrist2_0" class="right_ur5e/" file="wrist2_0-fdb3f7bc360f8f37f6be6270c8b507291dc9b01c.obj"/>
    <mesh name="right_ur5e/wrist2_1" class="right_ur5e/" file="wrist2_1-258ca475798c530d954723dc29f3d67086ead0d9.obj"/>
    <mesh name="right_ur5e/wrist2_2" class="right_ur5e/" file="wrist2_2-c6734971531db7f2f09e746377aa9faccb69b192.obj"/>
    <mesh name="right_ur5e/wrist3" class="right_ur5e/" file="wrist3-a1fffb4f599e121fb18be40e087b6fd7fb164e59.obj"/>
    <material name="right_ur5e/gripper/metal" class="right_ur5e/gripper/" rgba="0.57999999999999996 0.57999999999999996 0.57999999999999996 1"/>
    <material name="right_ur5e/gripper/silicone" class="right_ur5e/gripper/" rgba="0.18820000000000001 0.18820000000000001 0.18820000000000001 1"/>
    <material name="right_ur5e/gripper/gray" class="right_ur5e/gripper/" rgba="0.4627 0.4627 0.4627 1"/>
    <material name="right_ur5e/gripper/black" class="right_ur5e/gripper/" rgba="0.14899999999999999 0.14899999999999999 0.14899999999999999 1"/>
    <mesh name="right_ur5e/gripper/base_mount" class="right_ur5e/gripper/2f140" file="base_mount-37df51ceff1f5ba8141ffa5df4de2a9d9153a32c.stl" scale="0.001 0.001 0.001"/>
    <mesh name="right_ur5e/gripper/base" class="right_ur5e/gripper/2f140" file="base-42fe8832279fe72b3e5a9646845bae0aa01f30de.stl"/>
    <mesh name="right_ur5e/gripper/driver" class="right_ur5e/gripper/2f140" file="driver-23d09a5cdb42c23c510639985a63bcb1bfc67ae6.stl"/>
    <mesh name="right_ur5e/gripper/follower" class="right_ur5e/gripper/2f140" file="follower-f5f821e98b5292ecb13f9e0e91eb41ea73e64aac.stl"/>
    <mesh name="right_ur5e/gripper/coupler" class="right_ur5e/gripper/2f140" file="coupler-cc5b48743e92b0ae5d13d5ab9d2e23459ad8404c.stl"/>
    <mesh name="right_ur5e/gripper/pad" class="right_ur5e/gripper/2f140" file="pad-fe590c82ef16af878177e7dca8f9f69edd7773ad.stl" scale="0.001 0.001 0.001"/>
    <mesh name="right_ur5e/gripper/spring_link" class="right_ur5e/gripper/2f140" file="spring_link-17f0474146ce54aa2f0c0b0518c7403758e2f513.stl"/>
  </asset>
  <worldbody>
    <body name="vention_base" childclass="vention">
      <geom name="geom_0" class="visual" material="blue" mesh="vention_frame_visual_model"/>
      <geom name="geom_1" class="collision" type="box" size="0.65000000000000002 0.59999999999999998 0.371" pos="0 -0.47499999999999998 0.38250000000000001"/>
      <geom name="geom_2" class="collision" type="box" size="0.55000000000000004 0.125 0.66000000000000003" pos="0 -0.95999999999999996 1.4099999999999999"/>
      <geom name="geom_3" class="collision" type="box" size="0.036999999999999998 0.044999999999999998 0.071999999999999995" pos="-0.66000000000000003 -0.10000000000000001 0.71999999999999997"/>
      <body name="left_arm_vention_base" pos="-0.33000000000000002 -0.84799999999999998 1.6200000000000001">
        <geom name="geom_4" type="box" size="0.1125 0.01 0.1125" material="red" mass="18.57"/>
        <site name="left_arm_attachment_site" group="4" rgba="0.5 0.5 0.5 0.29999999999999999" size="0.01" pos="0 0.01 0" quat="0.5 -0.5 -0.5 -0.5"/>
        <body pos="0 0.01 0" quat="0.5 -0.5 -0.5 -0.5" name="left_ur5e/">
          <light name="left_ur5e/spotlight" class="left_ur5e/" mode="targetbodycom" target="left_ur5e/wrist_2_link" pos="0 -1 2"/>
          <body name="left_ur5e/base" childclass="left_ur5e/ur5e" quat="0 0 0 -1">
            <inertial pos="0 0 0" mass="4" diaginertia="0.0044333315599999999 0.0044333315599999999 0.0071999999999999998"/>
            <geom name="left_ur5e/geom_0" class="left_ur5e/visual" material="left_ur5e/black" mesh="left_ur5e/base_0"/>
            <geom name="left_ur5e/geom_1" class="left_ur5e/visual" material="left_ur5e/jointgray" mesh="left_ur5e/base_1"/>
            <body name="left_ur5e/shoulder_link" pos="0 0 0.16300000000000001">
              <inertial pos="0 0 0" mass="3.7000000000000002" diaginertia="0.010267500000000001 0.010267500000000001 0.0066600000000000001"/>
              <joint name="left_ur5e/shoulder_pan_joint" axis="0 0 1"/>
              <geom name="left_ur5e/geom_2" class="left_ur5e/visual" material="left_ur5e/urblue" mesh="left_ur5e/shoulder_0"/>
              <geom name="left_ur5e/geom_3" class="left_ur5e/visual" material="left_ur5e/black" mesh="left_ur5e/shoulder_1"/>
              <geom name="left_ur5e/geom_4" class="left_ur5e/visual" material="left_ur5e/jointgray" mesh="left_ur5e/shoulder_2"/>
              <geom name="left_ur5e/geom_5" class="left_ur5e/collision" size="0.059999999999999998 0.059999999999999998" pos="0 0 -0.040000000000000001"/>
              <body name="left_ur5e/upper_arm_link" pos="0 0.13800000000000001 0" quat="1 0 1 0">
                <inertial pos="0 0 0.21249999999999999" mass="8.3930000000000007" diaginertia="0.13388600000000001 0.13388600000000001 0.0151074"/>
                <joint name="left_ur5e/shoulder_lift_joint"/>
                <geom name="left_ur5e/geom_6" class="left_ur5e/visual" material="left_ur5e/linkgray" mesh="left_ur5e/upperarm_0"/>
                <geom name="left_ur5e/geom_7" class="left_ur5e/visual" material="left_ur5e/black" mesh="left_ur5e/upperarm_1"/>
                <geom name="left_ur5e/geom_8" class="left_ur5e/visual" material="left_ur5e/jointgray" mesh="left_ur5e/upperarm_2"/>
                <geom name="left_ur5e/geom_9" class="left_ur5e/visual" material="left_ur5e/urblue" mesh="left_ur5e/upperarm_3"/>
                <geom name="left_ur5e/geom_10" class="left_ur5e/collision" size="0.059999999999999998 0.059999999999999998" pos="0 -0.040000000000000001 0" quat="1 1 0 0"/>
                <geom name="left_ur5e/geom_11" class="left_ur5e/collision" size="0.050000000000000003 0.20000000000000001" pos="0 0 0.20000000000000001"/>
                <body name="left_ur5e/forearm_link" pos="0 -0.13100000000000001 0.42499999999999999">
                  <inertial pos="0 0 0.19600000000000001" mass="2.2749999999999999" diaginertia="0.031179599999999998 0.031179599999999998 0.0040949999999999997"/>
                  <joint name="left_ur5e/elbow_joint"/>
                  <geom name="left_ur5e/geom_12" class="left_ur5e/visual" material="left_ur5e/urblue" mesh="left_ur5e/forearm_0"/>
                  <geom name="left_ur5e/geom_13" class="left_ur5e/visual" material="left_ur5e/linkgray" mesh="left_ur5e/forearm_1"/>
                  <geom name="left_ur5e/geom_14" class="left_ur5e/visual" material="left_ur5e/black" mesh="left_ur5e/forearm_2"/>
                  <geom name="left_ur5e/geom_15" class="left_ur5e/visual" material="left_ur5e/jointgray" mesh="left_ur5e/forearm_3"/>
                  <geom name="left_ur5e/geom_16" class="left_ur5e/collision" size="0.055 0.059999999999999998" pos="0 0.080000000000000002 0" quat="1 1 0 0"/>
                  <geom name="left_ur5e/geom_17" class="left_ur5e/collision" size="0.037999999999999999 0.19" pos="0 0 0.20000000000000001"/>
                  <body name="left_ur5e/wrist_1_link" pos="0 0 0.39200000000000002" quat="1 0 1 0">
                    <inertial pos="0 0.127 0" mass="1.2190000000000001" diaginertia="0.0025598999999999999 0.0025598999999999999 0.0021941999999999999"/>
                    <joint name="left_ur5e/wrist_1_joint" class="left_ur5e/size1"/>
                    <geom name="left_ur5e/geom_18" class="left_ur5e/visual" material="left_ur5e/black" mesh="left_ur5e/wrist1_0"/>
                    <geom name="left_ur5e/geom_19" class="left_ur5e/visual" material="left_ur5e/urblue" mesh="left_ur5e/wrist1_1"/>
                    <geom name="left_ur5e/geom_20" class="left_ur5e/visual" material="left_ur5e/jointgray" mesh="left_ur5e/wrist1_2"/>
                    <geom name="left_ur5e/geom_21" class="left_ur5e/collision" size="0.040000000000000001 0.070000000000000007" pos="0 0.050000000000000003 0" quat="1 1 0 0"/>
                    <body name="left_ur5e/wrist_2_link" pos="0 0.127 0">
                      <inertial pos="0 0 0.10000000000000001" mass="1.2190000000000001" diaginertia="0.0025598999999999999 0.0025598999999999999 0.0021941999999999999"/>
                      <joint name="left_ur5e/wrist_2_joint" class="left_ur5e/size1" axis="0 0 1"/>
                      <geom name="left_ur5e/geom_22" class="left_ur5e/visual" material="left_ur5e/black" mesh="left_ur5e/wrist2_0"/>
                      <geom name="left_ur5e/geom_23" class="left_ur5e/visual" material="left_ur5e/urblue" mesh="left_ur5e/wrist2_1"/>
                      <geom name="left_ur5e/geom_24" class="left_ur5e/visual" material="left_ur5e/jointgray" mesh="left_ur5e/wrist2_2"/>
                      <geom name="left_ur5e/geom_25" class="left_ur5e/collision" size="0.040000000000000001 0.059999999999999998" pos="0 0 0.040000000000000001"/>
                      <geom name="left_ur5e/geom_26" class="left_ur5e/collision" size="0.040000000000000001 0.040000000000000001" pos="0 0.02 0.10000000000000001" quat="1 1 0 0"/>
                      <body name="left_ur5e/wrist_3_link" pos="0 0 0.10000000000000001">
                        <inertial pos="0 0.077168299999999995 0" quat="1 0 0 1" mass="0.18890000000000001" diaginertia="0.00013213400000000001 9.90863e-05 9.90863e-05"/>
                        <joint name="left_ur5e/wrist_3_joint" class="left_ur5e/size1"/>
                        <geom name="left_ur5e/geom_27" class="left_ur5e/visual" material="left_ur5e/linkgray" mesh="left_ur5e/wrist3"/>
                        <geom name="left_ur5e/geom_28" class="left_ur5e/eef_collision" size="0.040000000000000001 0.02" pos="0 0.080000000000000002 0" quat="1 1 0 0"/>
                        <site name="left_ur5e/gripper_attachment_site" pos="0 0.10000000000000001 0" quat="-1 1 0 0"/>
                      </body>
                    </body>
                  </body>
                </body>
              </body>
            </body>
          </body>
        </body>
      </body>
      <body name="right_arm_vention_base" pos="0.33000000000000002 -0.84799999999999998 1.6200000000000001">
        <geom name="geom_5" type="box" size="0.1125 0.01 0.1125" material="red" mass="18.57"/>
        <site name="right_arm_attachment_site" group="4" rgba="0.5 0.5 0.5 0.29999999999999999" size="0.01" pos="0 0.01 0" quat="0.5 -0.5 -0.5 -0.5"/>
        <body pos="0 0.01 0" quat="0.5 -0.5 -0.5 -0.5" name="right_ur5e/">
          <light name="right_ur5e/spotlight" class="right_ur5e/" mode="targetbodycom" target="right_ur5e/wrist_2_link" pos="0 -1 2"/>
          <body name="right_ur5e/base" childclass="right_ur5e/ur5e" quat="0 0 0 -1">
            <inertial pos="0 0 0" mass="4" diaginertia="0.0044333315599999999 0.0044333315599999999 0.0071999999999999998"/>
            <geom name="right_ur5e/geom_0" class="right_ur5e/visual" material="right_ur5e/black" mesh="right_ur5e/base_0"/>
            <geom name="right_ur5e/geom_1" class="right_ur5e/visual" material="right_ur5e/jointgray" mesh="right_ur5e/base_1"/>
            <body name="right_ur5e/shoulder_link" pos="0 0 0.16300000000000001">
              <inertial pos="0 0 0" mass="3.7000000000000002" diaginertia="0.010267500000000001 0.010267500000000001 0.0066600000000000001"/>
              <joint name="right_ur5e/shoulder_pan_joint" axis="0 0 1"/>
              <geom name="right_ur5e/geom_2" class="right_ur5e/visual" material="right_ur5e/urblue" mesh="right_ur5e/shoulder_0"/>
              <geom name="right_ur5e/geom_3" class="right_ur5e/visual" material="right_ur5e/black" mesh="right_ur5e/shoulder_1"/>
              <geom name="right_ur5e/geom_4" class="right_ur5e/visual" material="right_ur5e/jointgray" mesh="right_ur5e/shoulder_2"/>
              <geom name="right_ur5e/geom_5" class="right_ur5e/collision" size="0.059999999999999998 0.059999999999999998" pos="0 0 -0.040000000000000001"/>
              <body name="right_ur5e/upper_arm_link" pos="0 0.13800000000000001 0" quat="1 0 1 0">
                <inertial pos="0 0 0.21249999999999999" mass="8.3930000000000007" diaginertia="0.13388600000000001 0.13388600000000001 0.0151074"/>
                <joint name="right_ur5e/shoulder_lift_joint"/>
                <geom name="right_ur5e/geom_6" class="right_ur5e/visual" material="right_ur5e/linkgray" mesh="right_ur5e/upperarm_0"/>
                <geom name="right_ur5e/geom_7" class="right_ur5e/visual" material="right_ur5e/black" mesh="right_ur5e/upperarm_1"/>
                <geom name="right_ur5e/geom_8" class="right_ur5e/visual" material="right_ur5e/jointgray" mesh="right_ur5e/upperarm_2"/>
                <geom name="right_ur5e/geom_9" class="right_ur5e/visual" material="right_ur5e/urblue" mesh="right_ur5e/upperarm_3"/>
                <geom name="right_ur5e/geom_10" class="right_ur5e/collision" size="0.059999999999999998 0.059999999999999998" pos="0 -0.040000000000000001 0" quat="1 1 0 0"/>
                <geom name="right_ur5e/geom_11" class="right_ur5e/collision" size="0.050000000000000003 0.20000000000000001" pos="0 0 0.20000000000000001"/>
                <body name="right_ur5e/forearm_link" pos="0 -0.13100000000000001 0.42499999999999999">
                  <inertial pos="0 0 0.19600000000000001" mass="2.2749999999999999" diaginertia="0.031179599999999998 0.031179599999999998 0.0040949999999999997"/>
                  <joint name="right_ur5e/elbow_joint"/>
                  <geom name="right_ur5e/geom_12" class="right_ur5e/visual" material="right_ur5e/urblue" mesh="right_ur5e/forearm_0"/>
                  <geom name="right_ur5e/geom_13" class="right_ur5e/visual" material="right_ur5e/linkgray" mesh="right_ur5e/forearm_1"/>
                  <geom name="right_ur5e/geom_14" class="right_ur5e/visual" material="right_ur5e/black" mesh="right_ur5e/forearm_2"/>
                  <geom name="right_ur5e/geom_15" class="right_ur5e/visual" material="right_ur5e/jointgray" mesh="right_ur5e/forearm_3"/>
                  <geom name="right_ur5e/geom_16" class="right_ur5e/collision" size="0.055 0.059999999999999998" pos="0 0.080000000000000002 0" quat="1 1 0 0"/>
                  <geom name="right_ur5e/geom_17" class="right_ur5e/collision" size="0.037999999999999999 0.19" pos="0 0 0.20000000000000001"/>
                  <body name="right_ur5e/wrist_1_link" pos="0 0 0.39200000000000002" quat="1 0 1 0">
                    <inertial pos="0 0.127 0" mass="1.2190000000000001" diaginertia="0.0025598999999999999 0.0025598999999999999 0.0021941999999999999"/>
                    <joint name="right_ur5e/wrist_1_joint" class="right_ur5e/size1"/>
                    <geom name="right_ur5e/geom_18" class="right_ur5e/visual" material="right_ur5e/black" mesh="right_ur5e/wrist1_0"/>
                    <geom name="right_ur5e/geom_19" class="right_ur5e/visual" material="right_ur5e/urblue" mesh="right_ur5e/wrist1_1"/>
                    <geom name="right_ur5e/geom_20" class="right_ur5e/visual" material="right_ur5e/jointgray" mesh="right_ur5e/wrist1_2"/>
                    <geom name="right_ur5e/geom_21" class="right_ur5e/collision" size="0.040000000000000001 0.070000000000000007" pos="0 0.050000000000000003 0" quat="1 1 0 0"/>
                    <body name="right_ur5e/wrist_2_link" pos="0 0.127 0">
                      <inertial pos="0 0 0.10000000000000001" mass="1.2190000000000001" diaginertia="0.0025598999999999999 0.0025598999999999999 0.0021941999999999999"/>
                      <joint name="right_ur5e/wrist_2_joint" class="right_ur5e/size1" axis="0 0 1"/>
                      <geom name="right_ur5e/geom_22" class="right_ur5e/visual" material="right_ur5e/black" mesh="right_ur5e/wrist2_0"/>
                      <geom name="right_ur5e/geom_23" class="right_ur5e/visual" material="right_ur5e/urblue" mesh="right_ur5e/wrist2_1"/>
                      <geom name="right_ur5e/geom_24" class="right_ur5e/visual" material="right_ur5e/jointgray" mesh="right_ur5e/wrist2_2"/>
                      <geom name="right_ur5e/geom_25" class="right_ur5e/collision" size="0.040000000000000001 0.059999999999999998" pos="0 0 0.040000000000000001"/>
                      <geom name="right_ur5e/geom_26" class="right_ur5e/collision" size="0.040000000000000001 0.040000000000000001" pos="0 0.02 0.10000000000000001" quat="1 1 0 0"/>
                      <body name="right_ur5e/wrist_3_link" pos="0 0 0.10000000000000001">
                        <inertial pos="0 0.077168299999999995 0" quat="1 0 0 1" mass="0.18890000000000001" diaginertia="0.00013213400000000001 9.90863e-05 9.90863e-05"/>
                        <joint name="right_ur5e/wrist_3_joint" class="right_ur5e/size1"/>
                        <geom name="right_ur5e/geom_27" class="right_ur5e/visual" material="right_ur5e/linkgray" mesh="right_ur5e/wrist3"/>
                        <geom name="right_ur5e/geom_28" class="right_ur5e/eef_collision" size="0.040000000000000001 0.02" pos="0 0.080000000000000002 0" quat="1 1 0 0"/>
                        <site name="right_ur5e/gripper_attachment_site" pos="0 0.10000000000000001 0" quat="-1 1 0 0"/>
                        <body pos="0 0.10000000000000001 0" quat="-1 1 0 0" name="right_ur5e/gripper/">
                          <body name="right_ur5e/gripper/base_mount" childclass="right_ur5e/gripper/2f140" pos="0 0 0.0070000000000000001">
                            <geom name="right_ur5e/gripper/geom_0" class="right_ur5e/gripper/visual" material="right_ur5e/gripper/black" mesh="right_ur5e/gripper/base_mount"/>
                            <geom name="right_ur5e/gripper/geom_1" class="right_ur5e/gripper/collision" mesh="right_ur5e/gripper/base_mount"/>
                            <body name="right_ur5e/gripper/base" pos="0 0 0.0038" quat="1 0 0 -1">
                              <inertial pos="0 -2.7039400000000001e-05 0.035467499999999999" quat="1 -0.00152849 0 0" mass="0.77744100000000005" diaginertia="0.00026028500000000002 0.000225381 0.00015270799999999999"/>
                              <geom name="right_ur5e/gripper/geom_2" class="right_ur5e/gripper/visual" material="right_ur5e/gripper/black" mesh="right_ur5e/gripper/base"/>
                              <geom name="right_ur5e/gripper/geom_3" class="right_ur5e/gripper/collision" mesh="right_ur5e/gripper/base"/>
                              <body name="right_ur5e/gripper/right_driver" pos="0 0.030601 0.054905000000000002" quat="0 0 0.91190300000000002 0.41040500000000002">
                                <joint name="right_ur5e/gripper/right_driver_joint" class="right_ur5e/gripper/driver"/>
                                <geom name="right_ur5e/gripper/geom_4" class="right_ur5e/gripper/visual" material="right_ur5e/gripper/gray" mesh="right_ur5e/gripper/driver"/>
                                <geom name="right_ur5e/gripper/geom_5" class="right_ur5e/gripper/collision" mesh="right_ur5e/gripper/driver"/>
                                <body name="right_ur5e/gripper/right_coupler" pos="0 0.01822 0.026001" quat="1 0 0 0">
                                  <inertial pos="0.00016387500000000001 0.045840400000000003 -0.0117804" quat="0.88136800000000004 0.47242299999999998 -0.0024451 -0.00099612199999999989" mass="0.031146199999999999" diaginertia="2.9602299999999999e-05 2.7981399999999999e-05 4.3901700000000004e-06"/>
                                  <joint name="right_ur5e/gripper/right_coupler_joint" class="right_ur5e/gripper/coupler"/>
                                  <geom name="right_ur5e/gripper/geom_6" class="right_ur5e/gripper/visual" material="right_ur5e/gripper/black" mesh="right_ur5e/gripper/coupler"/>
                                  <geom name="right_ur5e/gripper/geom_7" class="right_ur5e/gripper/collision" mesh="right_ur5e/gripper/coupler"/>
                                </body>
                              </body>
                              <body name="right_ur5e/gripper/right_spring_link" pos="0 0.012699999999999999 0.061420000000000002" quat="0 0 -0.91354550000000001 -0.40673599999999999">
                                <inertial pos="0.00012301200000000001 0.0507851 0.00103969" quat="0.49720300000000001 0.50249600000000005 -0.50794300000000003 0.49222100000000002" mass="0.027117700000000002" diaginertia="2.8380900000000001e-05 2.6193599999999999e-05 2.8131900000000002e-06"/>
                                <joint name="right_ur5e/gripper/right_spring_link_joint" class="right_ur5e/gripper/spring_link"/>
                                <geom name="right_ur5e/gripper/geom_8" class="right_ur5e/gripper/visual" material="right_ur5e/gripper/black" mesh="right_ur5e/gripper/spring_link"/>
                                <geom name="right_ur5e/gripper/geom_9" class="right_ur5e/gripper/collision" mesh="right_ur5e/gripper/spring_link"/>
                                <body name="right_ur5e/gripper/right_follower" pos="0 0.10745399999999999 0.01451853" quat="0.93501299999999998 -0.35461300000000001 0 0">
                                  <inertial pos="0.000119314 0.0339244 -0.021840999999999999" quat="0.54543699999999995 0.430197 -0.442938 0.56677599999999995" mass="0.026150300000000001" diaginertia="1.6240799999999999e-05 1.5913099999999998e-05 2.3893600000000001e-06"/>
                                  <joint name="right_ur5e/gripper/right_follower_joint" class="right_ur5e/gripper/follower"/>
                                  <geom name="right_ur5e/gripper/geom_10" class="right_ur5e/gripper/visual" material="right_ur5e/gripper/black" mesh="right_ur5e/gripper/follower"/>
                                  <geom name="right_ur5e/gripper/geom_11" class="right_ur5e/gripper/collision" mesh="right_ur5e/gripper/follower"/>
                                  <body name="right_ur5e/gripper/right_pad" pos="0 0.012 -0.0276" quat="0.70710700000000004 -0.70710700000000004 0 0">
                                    <inertial pos="0 -0.0025000000000000001 0.018499999999999999" quat="0.70710700000000004 0 0 0.70710700000000004" mass="0.0035000000000000001" diaginertia="4.7395799999999999e-07 3.6458299999999998e-07 1.23958e-07"/>
                                    <geom name="right_ur5e/gripper/geom_12" class="right_ur5e/gripper/visual" mesh="right_ur5e/gripper/pad"/>
                                  </body>
                                  <geom name="right_ur5e/gripper/geom_13" class="right_ur5e/gripper/pad_box1"/>
                                </body>
                              </body>
                              <body name="right_ur5e/gripper/left_driver" pos="0 -0.030601099999999999 0.054904000000000001" quat="0.41040500000000002 0.91190300000000002 0 0">
                                <joint name="right_ur5e/gripper/left_driver_joint" class="right_ur5e/gripper/driver"/>
                                <geom name="right_ur5e/gripper/geom_14" class="right_ur5e/gripper/visual" material="right_ur5e/gripper/gray" mesh="right_ur5e/gripper/driver"/>
                                <geom name="right_ur5e/gripper/geom_15" class="right_ur5e/gripper/collision" mesh="right_ur5e/gripper/driver"/>
                                <body name="right_ur5e/gripper/left_coupler" pos="0 0.01822 0.026001" quat="1 0 0 0">
                                  <inertial pos="0.00016387500000000001 0.045840400000000003 -0.0117804" quat="0.88136800000000004 0.47242299999999998 -0.0024451 -0.00099612199999999989" mass="0.031146199999999999" diaginertia="2.9602299999999999e-05 2.7981399999999999e-05 4.3901700000000004e-06"/>
                                  <joint name="right_ur5e/gripper/left_coupler_joint" class="right_ur5e/gripper/coupler"/>
                                  <geom name="right_ur5e/gripper/geom_16" class="right_ur5e/gripper/visual" material="right_ur5e/gripper/black" mesh="right_ur5e/gripper/coupler"/>
                                  <geom name="right_ur5e/gripper/geom_17" class="right_ur5e/gripper/collision" mesh="right_ur5e/gripper/coupler"/>
                                </body>
                              </body>
                              <body name="right_ur5e/gripper/left_spring_link" pos="0 -0.012699999999999999 0.061420000000000002" quat="0.41040500000000002 0.91190300000000002 0 0">
                                <inertial pos="0.00012301200000000001 0.0507851 0.00103969" quat="0.49720300000000001 0.50249600000000005 -0.50794300000000003 0.49222100000000002" mass="0.027117700000000002" diaginertia="2.8380900000000001e-05 2.6193599999999999e-05 2.8131900000000002e-06"/>
                                <joint name="right_ur5e/gripper/left_spring_link_joint" class="right_ur5e/gripper/spring_link"/>
                                <geom name="right_ur5e/gripper/geom_18" class="right_ur5e/gripper/visual" material="right_ur5e/gripper/black" mesh="right_ur5e/gripper/spring_link"/>
                                <geom name="right_ur5e/gripper/geom_19" class="right_ur5e/gripper/collision" mesh="right_ur5e/gripper/spring_link"/>
                                <body name="right_ur5e/gripper/left_follower" pos="0 0.10745399999999999 0.01451853" quat="0.93501299999999998 -0.35461300000000001 0 0">
                                  <inertial pos="0.000119314 0.0339244 -0.021840999999999999" quat="0.54543699999999995 0.430197 -0.442938 0.56677599999999995" mass="0.026150300000000001" diaginertia="1.6240799999999999e-05 1.5913099999999998e-05 2.3893600000000001e-06"/>
                                  <joint name="right_ur5e/gripper/left_follower_joint" class="right_ur5e/gripper/follower"/>
                                  <geom name="right_ur5e/gripper/geom_20" class="right_ur5e/gripper/visual" material="right_ur5e/gripper/black" mesh="right_ur5e/gripper/follower"/>
                                  <geom name="right_ur5e/gripper/geom_21" class="right_ur5e/gripper/collision" mesh="right_ur5e/gripper/follower"/>
                                  <body name="right_ur5e/gripper/left_pad" pos="0 0.012 -0.0276" quat="0.70710700000000004 -0.70710700000000004 0 0">
                                    <inertial pos="0 -0.0025000000000000001 0.018499999999999999" quat="1 0 0 1" mass="0.0035000000000000001" diaginertia="4.7395799999999999e-07 3.6458299999999998e-07 1.23958e-07"/>
                                    <geom name="right_ur5e/gripper/geom_22" class="right_ur5e/gripper/visual" mesh="right_ur5e/gripper/pad"/>
                                  </body>
                                  <geom name="right_ur5e/gripper/geom_23" class="right_ur5e/gripper/pad_box1"/>
                                </body>
                              </body>
                            </body>
                          </body>
                        </body>
                      </body>
                    </body>
                  </body>
                </body>
              </body>
            </body>
          </body>
        </body>
      </body>
    </body>
    <site name="world_site" class="/" rgba="0.20000000000000001 0.20000000000000001 0.80000000000000004 0.5" size="0.050000000000000003" pos="0 0 0"/>
    <body pos="0 0 0" name="camera_with_mount/">
      <body name="camera_with_mount/camera_mount_front_horizontal" pos="0 0.17000000000000001 0.72999999999999998" euler="-1.57079632679 0 0">
        <geom name="camera_with_mount/cmfh_visual" class="camera_with_mount/" type="box" size="0.022499999999999999 0.022499999999999999 0.089999999999999997" rgba="0.10000000000000001 0.16 0.23999999999999999 1"/>
        <geom name="camera_with_mount/cmfh_collision" class="camera_with_mount/" type="box" contype="1" conaffinity="1" size="0.037499999999999999 0.037499999999999999 0.089999999999999997" rgba="0.69999999999999996 0.69999999999999996 0.69999999999999996 1"/>
        <body name="camera_with_mount/camera_mount_front_vertical" pos="0 -0.17749999999999999 0.1125" euler="1.57079632679 0 0">
          <geom name="camera_with_mount/cmfv_visual" class="camera_with_mount/" type="box" size="0.022499999999999999 0.022499999999999999 0.20000000000000001" rgba="0.10000000000000001 0.16 0.23999999999999999 1"/>
          <geom name="camera_with_mount/cmfv_collision" class="camera_with_mount/" type="box" contype="1" conaffinity="1" size="0.037499999999999999 0.037499999999999999 0.20000000000000001" rgba="0.69999999999999996 0.69999999999999996 0.69999999999999996 1"/>
          <body name="camera_with_mount/front_print" pos="0 0 0.20000000000000001" euler="1.57079632679 0 3.1415926535900001">
            <geom name="camera_with_mount/front_print_collision" class="camera_with_mount/" type="box" contype="1" conaffinity="1" size="0.14999999999999999 0.14999999999999999 0.14999999999999999" rgba="0.69999999999999996 0.69999999999999996 0.69999999999999996 0.25"/>
            <geom name="camera_with_mount/front_print_visual" class="camera_with_mount/" type="box" size="0.14999999999999999 0.14999999999999999 0.14999999999999999" rgba="0.69999999999999996 0.69999999999999996 0.69999999999999996 0.25"/>
          </body>
        </body>
      </body>
    </body>
  </worldbody>
  <contact>
    <exclude name="right_ur5e/gripper//unnamed_contact_0" body1="right_ur5e/gripper/base" body2="right_ur5e/gripper/left_driver"/>
    <exclude name="right_ur5e/gripper//unnamed_contact_1" body1="right_ur5e/gripper/base" body2="right_ur5e/gripper/right_driver"/>
    <exclude name="right_ur5e/gripper//unnamed_contact_2" body1="right_ur5e/gripper/base" body2="right_ur5e/gripper/left_spring_link"/>
    <exclude name="right_ur5e/gripper//unnamed_contact_3" body1="right_ur5e/gripper/base" body2="right_ur5e/gripper/right_spring_link"/>
    <exclude name="right_ur5e/gripper//unnamed_contact_4" body1="right_ur5e/gripper/left_driver" body2="right_ur5e/gripper/left_spring_link"/>
    <exclude name="right_ur5e/gripper//unnamed_contact_5" body1="right_ur5e/gripper/right_driver" body2="right_ur5e/gripper/right_spring_link"/>
    <exclude name="right_ur5e/gripper//unnamed_contact_6" body1="right_ur5e/gripper/right_coupler" body2="right_ur5e/gripper/right_follower"/>
    <exclude name="right_ur5e/gripper//unnamed_contact_7" body1="right_ur5e/gripper/left_coupler" body2="right_ur5e/gripper/left_follower"/>
  </contact>
  <equality>
    <connect name="right_ur5e/gripper//unnamed_equality_0" class="right_ur5e/gripper/" solref="0.0050000000000000001 1" solimp="0.94999999999999996 0.98999999999999999 0.001" body1="right_ur5e/gripper/right_follower" body2="right_ur5e/gripper/right_coupler" anchor="0 0 0"/>
    <connect name="right_ur5e/gripper//unnamed_equality_1" class="right_ur5e/gripper/" solref="0.0050000000000000001 1" solimp="0.94999999999999996 0.98999999999999999 0.001" body1="right_ur5e/gripper/left_follower" body2="right_ur5e/gripper/left_coupler" anchor="0 0 0"/>
    <joint name="right_ur5e/gripper//unnamed_equality_2" class="right_ur5e/gripper/" solref="0.0050000000000000001 1" solimp="0.94999999999999996 0.98999999999999999 0.001" joint1="right_ur5e/gripper/right_driver_joint" joint2="right_ur5e/gripper/left_driver_joint" polycoef="0 1 0 0 0"/>
  </equality>
  <tendon>
    <fixed name="right_ur5e/gripper/split" class="right_ur5e/gripper/">
      <joint joint="right_ur5e/gripper/right_driver_joint" coef="-0.5"/>
      <joint joint="right_ur5e/gripper/left_driver_joint" coef="-0.5"/>
    </fixed>
  </tendon>
  <actuator>
    <general name="left_ur5e/shoulder_pan" class="left_ur5e/ur5e" joint="left_ur5e/shoulder_pan_joint"/>
    <general name="left_ur5e/shoulder_lift" class="left_ur5e/ur5e" joint="left_ur5e/shoulder_lift_joint"/>
    <general name="left_ur5e/elbow" class="left_ur5e/ur5e" joint="left_ur5e/elbow_joint"/>
    <general name="left_ur5e/wrist_1" class="left_ur5e/size1" joint="left_ur5e/wrist_1_joint"/>
    <general name="left_ur5e/wrist_2" class="left_ur5e/size1" joint="left_ur5e/wrist_2_joint"/>
    <general name="left_ur5e/wrist_3" class="left_ur5e/size1" joint="left_ur5e/wrist_3_joint"/>
    <general name="right_ur5e/shoulder_pan" class="right_ur5e/ur5e" joint="right_ur5e/shoulder_pan_joint"/>
    <general name="right_ur5e/shoulder_lift" class="right_ur5e/ur5e" joint="right_ur5e/shoulder_lift_joint"/>
    <general name="right_ur5e/elbow" class="right_ur5e/ur5e" joint="right_ur5e/elbow_joint"/>
    <general name="right_ur5e/wrist_1" class="right_ur5e/size1" joint="right_ur5e/wrist_1_joint"/>
    <general name="right_ur5e/wrist_2" class="right_ur5e/size1" joint="right_ur5e/wrist_2_joint"/>
    <general name="right_ur5e/wrist_3" class="right_ur5e/size1" joint="right_ur5e/wrist_3_joint"/>
    <position name="right_ur5e/gripper/fingers_actuator" class="right_ur5e/gripper/" ctrlrange="-0.80000000000000004 0" joint="right_ur5e/gripper/right_driver_joint" kp="200"/>
  </actuator>
</mujoco>
